Workbook

Sheet Synthèse
A1: Mise en données des matériaux — synthèse
A2: D'où viennent les proportions portées dans data/mixtures/*.xml : hypothèses, étapes et formules, un onglet par matériau
A3: Fichier(s) XML : data/mixtures/ — 12 matériaux, 21 fichiers de mélange
A5: §1 — MODE D'EMPLOI
B6: Chaque onglet matériau reconstruit, ÉTAPE PAR ÉTAPE ET EN FORMULES VIVANTES, la chaîne qui mène de la donnée expérimentale publiée aux trois nombres portés dans le fichier XML. Modifier une cellule bleue (donnée d'entrée) recalcule toute la chaîne jusqu'à la composition, et jusqu'à l'écart affiché avec la valeur réellement présente dans le dépôt.
B7: Trame commune à tous les onglets : §0 fiche d'identité · §1 hypothèses · §2 données d'entrée (avec sources) · §3 calcul pas à pas · §4 résultat porté dans le XML · §5 contrôles et validation croisée · §6 sensibilité · §7 réponse matériau (hors XML) · §8 bloc XML.
B8: L'onglet Constantes porte les masses molaires, l'air de couche limite, les motifs de résine et le rappel du bilan de masse de surface — il est référencé par tous les autres.
A10: §2 — TABLEAU DE SYNTHÈSE : LES COMPOSITIONS DES XML
B11: Matériau (onglet) | C11: gaz — C | D11: gaz — H | E11: gaz — O | F11: H/O | G11: char | H11: k = B'g/B'c
B12: TACOT | C12: ='TACOT'!C73 -> 0.206 | D12: ='TACOT'!D73 -> 0.679 | E12: ='TACOT'!E73 -> 0.115 | F12: ='TACOT'!D73/'TACOT'!E73 -> 5.9043478 | G12: C:1.0 | H12: ='TACOT'!C103 -> 0.27272727
B13: CPh70 | C13: ='CPh70'!C48 -> 0.206 | D13: ='CPh70'!D48 -> 0.679 | E13: ='CPh70'!E48 -> 0.115 | F13: ='CPh70'!D48/'CPh70'!E48 -> 5.9043478 | G13: C:1.0 | H13: ='CPh70'!C43 -> 0.13846154
B14: ZURAM 18/50 | C14: ='ZURAM'!C59 -> 0.171 | D14: ='ZURAM'!D59 -> 0.722 | E14: ='ZURAM'!E59 -> 0.107 | F14: ='ZURAM'!D59/'ZURAM'!E59 -> 6.7476636 | G14: C:1.0 | H14: ='ZURAM'!C106 -> 0.24101132
B15: SC-1008 (PICA) | C15: ='SC-1008'!C55 -> 0.2526 | D15: ='SC-1008'!D55 -> 0.6407 | E15: ='SC-1008'!E55 -> 0.1068 | F15: ='SC-1008'!D55/'SC-1008'!E55 -> 5.9990637 | G15: C:1.0 | H15: ='SC-1008'!C126 -> 0.2345679
B16: MX-4926 | C16: ='MX-4926'!C68 -> 0.2526 | D16: ='MX-4926'!D68 -> 0.6407 | E16: ='MX-4926'!E68 -> 0.1068 | F16: ='MX-4926'!D68/'MX-4926'!E68 -> 5.9990637 | G16: C:1.0 | H16: ='MX-4926'!C56 -> 0.1816839
B17: Liège/phénolique | C17: ='Liège-phénolique'!C80 -> 0.287 | D17: ='Liège-phénolique'!D80 -> 0.592 | E17: ='Liège-phénolique'!E80 -> 0.121 | F17: ='Liège-phénolique'!D80/'Liège-phénolique'!E80 -> 4.892562 | G17: C:1.0 | H17: ='Liège-phénolique'!C120 -> 4
B18: Bois de chêne | C18: ='Chêne'!C67 -> 0.221 | D18: ='Chêne'!D67 -> 0.536 | E18: ='Chêne'!E67 -> 0.243 | F18: ='Chêne'!D67/'Chêne'!E67 -> 2.2057613 | G18: C:1.0 | H18: ='Chêne'!C106 -> 4
B19: Carbone graphite | C19: — | D19: — | E19: — | F19: — | G19: C:1.0 | H19: ='Carbone'!C53 -> 0
B20: Silice SiO2 | C20: — | D20: — | E20: — | F20: — | G20: Si:1.0, O:2.0 | H20: ='Silice'!C46 -> 0
B21: Carbure de silicium SiC | C21: — | D21: — | E21: — | F21: — | G21: Si:1.0, C:1.0 | H21: ='SiC'!C69 -> 0
B22: Molybdène (TZM) | C22: — | D22: — | E22: — | F22: — | G22: Mo:1.0 | H22: ='Molybdène'!C53 -> 0
B23: Les colonnes « gaz » sont des liens vers la ligne « valeur portée dans le XML » de chaque onglet. Le graphite, la silice, le SiC et le molybdène n'ont pas de gaz de pyrolyse (k = 0). TACOT et CPh70 portent RIGOUREUSEMENT la même composition : leurs fichiers XML sont identiques, seul k les distingue — c'est la démonstration de l'onglet CPh70.
A25: §3 — LES TROIS SEULES DONNÉES QUE CONSOMME LE CALCUL
B26: # | C26: Composition | D26: Rôle dans le bilan | E26: Option | F26: Comment on l'obtient
B27: 1 | C27: bord de couche limite | D27: Y_e | E27: -bl | F27: l'atmosphère : air N:0.79 O:0.21 · Mars · Titan…
B28: 2 | C28: gaz de pyrolyse | D28: Y_g | E28: -py | F28: c'est TOUT l'objet de ce classeur — quatre routes possibles, §4
B29: 3 | C29: char | D29: Y_c | E29: -char + -char-elem | F29: C:1.0 si tous les constituants carbonisent vers le carbone ; sinon pondérer par les masses de char
B30: Plus T, P et B'g. Rien d'autre : cf. src/apps/bprime.cpp:304-330. Sans -char/-char-elem, bprime utilise un char de carbone pur intégré ; les deux options vont toujours ensemble.
A32: §4 — LES QUATRE ROUTES DE CALCUL DU GAZ DE PYROLYSE
B33: Route | C33: Matériau | D33: Donnée primaire | E33: Passage à l'élémentaire | F33: Point critique
B34: A — sommation atomique | C34: TACOT, CPh70 | D34: spéciation moléculaire mesurée (7 espèces) | E34: n_E = Σ_j ν_E,j · x_j | F34: la renormalisation : somme réelle des colonnes (100.30), pas les totaux imprimés (100.0)
B35: B — conversion directe | C35: ZURAM | D35: composition élémentaire MASSIQUE mesurée | E35: x_E = (y_E/M_E) / Σ (y_j/M_j) | F35: traçabilité limitée à 3 décimales ; la source primaire VKI n'est pas publique
B36: C — fermeture élémentaire | C36: SC-1008, Chêne | D36: motif idéalisé (SC-1008) ou analyse élémentaire (chêne) + rendement en char | E36: n_E(gaz) = n_E(solide) − n_E(char) | F36: le rendement en char entre DANS la chaîne : ±0.05 sur Y déplace le carbone de ~12 %
B37: D — fermeture sur DEUX constituants | C37: Liège/phénolique | D37: analyses des deux constituants + rendements | E37: n_E(gaz) = Σ_i [n_E(i) − n_E(char,i)] | F37: le renfort pyrolyse : le rapport renfort/résine entre dans la table B'
B38: E — stœchiométrie directe | C38: Carbone, Silice, SiC, Mo | D38: la formule du solide | E38: aucun gaz de pyrolyse (B'g = 0) | F38: le char EST le matériau ; -char-elem Si pour la silice, N pour le SiC (char non congruent)
A40: §5 — CE QUI N'ENTRE PAS DANS LE XML
B41: Donnée | C41: Dans le XML ? | D41: Où elle sert vraiment
B42: masse volumique ρ_v, ρ_c | C42: non | D42: solveur de réponse matériau ; récession ṡ = B'c·ṁe/ρ_c
B43: porosité | C43: non | D43: conduction, perméabilité
B44: rapport fibres/résine | C44: non * | D44: fixe la QUANTITÉ de gaz (donc B'g), pas sa composition
B45: rendement en char | C45: non * | D45: idem — mais il entre dans le CALCUL du gaz pour les routes C et D
...

Sheet Constantes
A1: Constantes et conventions communes
A2: Masses molaires, air de couche limite, motifs de résine, bilan de masse de surface — référencés par tous les onglets matériaux
A3: Fichier(s) XML : toutes les mises en données de data/mixtures/
A5: §1 — MASSES MOLAIRES DES ÉLÉMENTS
B6: Élément | C6: M usuelle [g/mol] | D6: M classeur ZURAM [g/mol]
B7: Carbone C | C7: 12.011 | D7: 12.0107
B8: Hydrogène H | C8: 1.008 | D8: 1.00794
B9: Oxygène O | C9: 15.999 | D9: 15.999
B10: Azote N | C10: 14.007 | D10: —
B11: Silicium Si | C11: 28.0855 | D11: —
B12: Colonne « usuelle » : valeurs employées par les scripts du dépôt (cork_pyrolysis_data.py). Colonne « classeur ZURAM » : valeurs de Tacot_Zuram_Calcarb_database_v4.3.1.ods, onglet ZURAM_official!F87:F89 — elles seules reproduisent les fractions molaires de ce classeur au 1e-16 près.
A14: §2 — BORD DE COUCHE LIMITE : L'AIR (identique dans tous les XML)
B15: Air (option -bl) | C15: N | D15: O | E15: Somme
B16: fraction molaire élémentaire x_E (XML) | C16: 0.79 | D16: 0.21 | E16: =SUM(C16:D16) -> 1
B17: masse molaire M_E [g/mol] | C17: =Constantes!$C$10 -> 14.007 | D17: =Constantes!$C$9 -> 15.999
B18: x_E · M_E | C18: =C16*C17 -> 11.06553 | D18: =D16*D17 -> 3.35979 | E18: =SUM(C18:D18) -> 14.42532
B19: fraction massique élémentaire y_E | C19: =C18/$E$18 -> 0.76709078 | D19: =D18/$E$18 -> 0.23290922 | E19: =SUM(C19:D19) -> 1
B20: y_E = x_E·M_E / Σ x_j·M_j. Le parseur de Mutation++ normalise seul la somme à 1 et convertit mole ↔ masse (Mixture.cpp:131-138) : `type="mole"` est le défaut, `type="mass"` doit être déclaré explicitement si la source est massique.
A22: §3 — MOTIFS DE RÉSINE PHÉNOLIQUE (référence commune TACOT / ZURAM / SC-1008 / liège)
A23: > | B23: Un motif cuit s'écrit C(6+b)H6O : un cycle phénolique et b ponts méthylène –CH2–. | I23: M = ν_C·M_C + ν_H·M_H + ν_O·M_O ; w_E = ν_E·M_E / M
B24: Motif | C24: ν_C | D24: ν_H | E24: ν_O | F24: % C masse | G24: % H masse | H24: % O masse
B25: phénol C6H6O (monomère) | C25: 6 | D25: 6 | E25: 1 | F25: =C25*Constantes!$C$7/(C25*Constantes!$C$7+D25*Constantes!$C$8+E25*Constantes!$C$9)*100 -> 76.573906 | G25: =D25*Constantes!$C$8/(C25*Constantes!$C$7+D25*Constantes!$C$8+E25*Constantes!$C$9)*100 -> 6.4263173 | H25: =E25*Constantes!$C$9/(C25*Constantes!$C$7+D25*Constantes!$C$8+E25*Constantes!$C$9)*100 -> 16.999777 | I25: TACOT : motif équivalent mesuré (Sykes table II), à 0.85 point près
B26: novolac linéaire C7H6O (b = 1) | C26: 7 | D26: 6 | E26: 1 | F26: =C26*Constantes!$C$7/(C26*Constantes!$C$7+D26*Constantes!$C$8+E26*Constantes!$C$9)*100 -> 79.225246 | G26: =D26*Constantes!$C$8/(C26*Constantes!$C$7+D26*Constantes!$C$8+E26*Constantes!$C$9)*100 -> 5.6989936 | H26: =E26*Constantes!$C$9/(C26*Constantes!$C$7+D26*Constantes!$C$8+E26*Constantes!$C$9)*100 -> 15.07576 | I26: ZURAM : motif équivalent mesuré ([THo] fig. 7), à 0.35 point près ; liège : motif retenu pour la résine
B27: résol saturé / réticulé C7.5H6O (b = 1.5) | C27: 7.5 | D27: 6 | E27: 1 | F27: =C27*Constantes!$C$7/(C27*Constantes!$C$7+D27*Constantes!$C$8+E27*Constantes!$C$9)*100 -> 80.337913 | G27: =D27*Constantes!$C$8/(C27*Constantes!$C$7+D27*Constantes!$C$8+E27*Constantes!$C$9)*100 -> 5.3937635 | H27: =E27*Constantes!$C$9/(C27*Constantes!$C$7+D27*Constantes!$C$8+E27*Constantes!$C$9)*100 -> 14.268324 | I27: SC-1008 : motif RETENU (résol saturé) — M = 112.13 g/mol
B28: Le nombre de ponts b n'est pas un réglage libre : le phénol a 3 sites réactifs (2 ortho + 1 para) et un pont est partagé entre 2 cycles, d'où b ≤ 1.5 à réseau saturé. Novolac (formé en défaut de formaldéhyde, durci à l'hexamine) et résol (excès de formaldéhyde, auto-réticulant) glissent sur la MÊME courbe : seul b diffère. L'analyse élémentaire C/H/O ne permet donc pas de distinguer les deux — seul l'azote le fait.
A30: §4 — LE BILAN QUI CONSOMME CES COMPOSITIONS (rappel)
B31: Bilan de conservation de chaque élément i à la paroi, couche limite laminaire à nombre de Lewis unité :
B32: (1 + B'c + B'g) · Y_w,i = Y_e,i + B'c · Y_c,i + B'g · Y_g,i
B34: => B'c = [ Y_e,i + B'g·Y_g,i − Y_w,i·(1 + B'g) ] / ( Y_w,i − Y_c,i )
B35: Y_e = bord de couche limite (option -bl) · Y_g = gaz de pyrolyse (-py) · Y_c = char (-char, avec -char-elem) · Y_w = gaz à la paroi, calculé à l'équilibre thermochimique à (T_w, P). `bprime` ne consomme QUE ces trois compositions élémentaires, plus T, P et B'g (src/apps/bprime.cpp:304-330).
B36: Conséquence majeure : aucune grandeur volumique (masse volumique, porosité, rapport fibres/résine, rendement en char, cinétique) n'entre dans le XML. Toutes vivent dans le solveur de réponse matériau — voir le §7 de chaque onglet.
A38: §5 — LÉGENDE DES COULEURS ET MODE D'EMPLOI
B39: bleu — donnée d'entrée en dur : mesure, valeur publiée, hypothèse. C'est ici qu'on édite.
B40: noir — cellule calculée par formule vivante. Ne pas écraser.
B41: vert — lien vers un autre onglet (constantes, ou composition héritée d'un autre matériau).
B42: rouge sur fond rosé — la valeur telle qu'elle figure dans le fichier XML du dépôt.
B43: fond jaune — hypothèse clé : c'est le paramètre dont dépend le plus le résultat.
B45: Chaque onglet matériau suit la même trame : §0 fiche d'identité · §1 hypothèses · §2 données d'entrée · §3 calcul pas à pas · §4 résultat porté dans le XML · §5 contrôles et validation croisée · §6 sensibilité · §7 réponse matériau (hors XML) · §8 bloc XML.

Sheet TACOT
A1: TACOT — Theoretical Ablative Composite for Open Testing
A2: Carbone/phénolique poreux · gaz de pyrolyse obtenu par SOMMATION ATOMIQUE d'une spéciation moléculaire mesurée
A3: Fichier(s) XML : data/mixtures/tacot-air_25.xml · tacot-air_35.xml · tacot-pyrogas.xml
A5: §0 — FICHE D'IDENTITÉ
B6: Matériau | C6: TACOT 3.0 (matériau de référence ouvert) | I6: Classeur TACOT_3.0.xls, onglet Description
B7: Renfort | C7: fibres de carbone ex-cellulose, traitées à 2000 K, 1600 kg/m³ | I7: Description!A11 — « The carbon fibers do not pyrolyse » ('Pyrolysis model'!H20)
B8: Résine | C8: novolac phénol-formaldéhyde Union Carbide BRP 5549 + hexamine (HMTA), 1200 kg/m³ | I8: Sykes, NASA TN D-3810 (1967), § MATERIAL p. 2 ; Description!A12
B9: Microstructure | C9: ε_fibres 0.10 / ε_matrice 0.10 / porosité 0.80 | I9: Description!A15:A17
B10: Source primaire du gaz | C10: Sykes, table I (chromatographie, paliers de 50 °C entre 100 et 1000 °C) | I10: reprise dans 'Pyrolysis-gas chemistry'!B5:H5 puis 'Pyrolysis model'!B4:B6
B11: Compositions du XML | C11: air (-bl) · tacot_pyro (-py) · tacot_char (-char, -char-elem C) | I11: tacot_bprime/resine_tacot.md et mise_en_donnees_xml.md
A13: §1 — HYPOTHÈSES
A14: H1 | B14: Le gaz de pyrolyse est produit par la RÉSINE SEULE. | I14: Les fibres ex-cellulose sont déjà traitées à 2000 K : elles ne pyrolysent pas ('Pyrolysis model'!H20). Le rapport fibres/résine ne fixe donc que la QUANTITÉ de gaz (donc B'g), pas sa composition — cf. onglet CPh70.
A15: H2 | B15: La spéciation retenue est la somme RÉELLE des colonnes de la table I de Sykes (100.30), pas les totaux imprimés arrondis (100.0). | I15: C'est ce choix, et lui seul, qui permet de reproduire le classeur TACOT 3.0 au 1e-16 près (§5).
A16: H3 | B16: Réduction du modèle : toluène C7H8 → benzène C6H6, et 2,4-xylénol C8H10O → phénol C6H5OH. | I16: 'Pyrolysis-gas chemistry'!A8 : compatibilité avec le mécanisme cinétique d'April (10 réactions), qui ignore toluène et xylénol. Conservative en atomes à ~1 % près (C7H8→C6H6 perd un CH2).
A17: H4 | B17: Le gaz est déclaré SANS AZOTE. | I17: Les 2.35 % de N de la résine viennent de la HMTA prémélangée ; ils s'effondrent à 0.42 % dès 400 °C et à zéro à 500 °C (Sykes table II) : signature d'un composé piégé, pas d'un azote de structure.
A18: H5 | B18: Le char est du carbone pur : C:1.0. | I18: Sykes mesure pourtant C 92.65 / H 0.90 / O 6.45 % à 850 °C. L'hypothèse reste licite en ablation : la paroi dépasse 2000 K (l'oxygène résiduel part en CO bien avant) et les fibres, 57 % de la masse vierge, sont déjà du carbone pur.
A19: H6 | B19: Le gaz à la paroi est à l'équilibre thermochimique à (T_w, P). | I19: Hypothèse centrale de la table B'. Le solveur multiphase de Mutation++ traite la coexistence gaz / C(gr).
A20: H7 | B20: Liste d'espèces = les 25 espèces gazeuses de la table B' de référence, PLUS la phase condensée C(gr). | I20: Sans C(gr) l'excès de carbone ne peut pas se condenser : Y_w,C → 1 et B'c sature vers ≈ 200 au lieu de ≈ 0.087 à 300 K. La liste conditionne le résultat : 25 espèces donnent 0.43 % d'écart moyen contre la table de référence, 35 espèces 2.41 %.
A22: §2 — DONNÉES D'ENTRÉE
A23: > | B23: Table I de Sykes — distribution des produits de décomposition, en % des moles totales observées | I23: somme sur les 19 paliers de température
B24: Espèce (table I) | C24: Σ colonne (réelle) | D24: total imprimé | E24: après réduction H3
B25: CO2 | C25: 1.57 | D25: 1.6 | E25: CO2
B26: CO | C26: 5.78 | D26: 5.5 | E26: CO
B27: C6H6 benzène | C27: 0.17 | D27: 0.2 | E27: C6H6
B28: C7H8 toluène | C28: 0.31 | D28: 0.3 | E28: → C6H6
B29: C6H5OH phénol | C29: 7.14 | D29: 7.1 | E29: C6H5OH
B30: (CH3)2C6H3OH xylénol | C30: 1.8 | D30: 1.8 | E30: → C6H5OH
B31: CH4 | C31: 10.03 | D31: 10 | E31: CH4
B32: H2O | C32: 23.43 | D32: 23.4 | E32: H2O
B33: H2 | C33: 50.07 | D33: 50.1 | E33: H2
B34: SOMME | C34: =SUM(C25:C33) -> 100.3 | D34: =SUM(D25:D33) -> 100 | E34: ← 100.30 contre 100.0 : voir H2
B35: Les totaux imprimés au bas de la table de Sykes sont arrondis et somment à 100.0 ; les colonnes elles-mêmes somment à 100.30. C'est cette dernière valeur que le classeur TACOT 3.0 utilise pour renormaliser.
B37: Analyse élémentaire de la résine vierge — C [% masse] | C37: 75.6 | I37: Sykes, table II, ligne « ambiant ». L'analyse ne dose que C, H et N ; O est le complément à 100 % (cendres mesurées à 0.04 %, négligeables).
B38: H [% masse] | C38: 6.12
B39: N [% masse] | C39: 2.35 | I39: issu de la HMTA — retiré du gaz, cf. H4
B40: O [% masse] | C40: 15.93 | I40: complément à 100 %
B41: Rendement en char de la résine — mesuré | C41: 0.54 | I41: Sykes table II : fraction massique résiduelle à 850 °C
B42: Rendement en char de la résine — modèle TACOT | C42: 0.5 | I42: implicite : microstructure ('Pyrolysis model'!A32:A34) ET cinétique de Goldstein (B18:C19) donnent 0.50 toutes deux
B43: ρ fibres / ρ résine [kg/m³] | C43: 1600 | I43: Description!A11
C44: 1200 | I44: Description!A12
...

Sheet CPh70
A1: CPh70 — carbone/phénolique dense
A2: Mêmes fibres et même résine que le TACOT, autres proportions · démontre que le rapport fibres/résine N'ENTRE PAS dans le XML
A3: Fichier(s) XML : data/mixtures/cph70-air_25.xml
A5: §0 — FICHE D'IDENTITÉ
B6: Matériau | C6: CPh70 — composite carbone/phénolique dense | I6: 70 % fibres / 30 % résine en volume solide, porosité 0.01
B7: Renfort | C7: fibres de carbone ex-cellulose, 1600 kg/m³ — IDENTIQUES au TACOT | I7: cf. onglet TACOT §0
B8: Résine | C8: novolac/formaldéhyde, 1200 kg/m³ — IDENTIQUE au TACOT | I8: cf. onglet TACOT §0
B9: Source du gaz | C9: héritée du TACOT (résine inchangée) | I9: tacot_bprime/cph70_vs_tacot.md
B10: Compositions du XML | C10: air (-bl) · cph70_pyro (-py) · cph70_char (-char, -char-elem C) | I10: cph70_bprime/README.md
A12: §1 — HYPOTHÈSES
A13: H1 | B13: Fibres et résine RIGOUREUSEMENT identiques à celles du TACOT ; seuls changent les proportions et la porosité. | I13: C'est la définition même du cas d'étude. Si la résine ou la nature des fibres changeait, tout le §3 serait à refaire.
A14: H2 | B14: Le gaz de pyrolyse est produit par la résine seule ⇒ sa composition ÉLÉMENTAIRE est inchangée. | I14: Changer le rapport fibres/résine change la QUANTITÉ de gaz produite (donc B'g), pas sa composition. Or B'g est un paramètre d'ENTRÉE de la table, balayé de 0 à 10.
A15: H3 | B15: Fibres de carbone et résine carbonisée donnent toutes deux du carbone pur ⇒ char C:1.0 quelles que soient les proportions. | I15: La pondération générale n_E(char) = Σ_i (m_char,i/M_i)·ν_E,i se réduit à C:1.0 dès que tous les constituants carbonisent vers le même élément.
A16: H4 | B16: Aucune grandeur volumique n'entre dans le bilan de surface. | I16: Le bilan est écrit sur des fractions massiques élémentaires, donc normalisées : ni ρ, ni porosité, ni ε_f n'y apparaissent (Constantes §4).
A17: H5 | B17: Rendement en char de la résine : 0.50 (valeur du modèle TACOT). | I17: Elle n'entre pas dans le XML — seulement dans ρ_char, donc dans k (§7).
A19: §2 — DONNÉES D'ENTRÉE
B20: fraction volumique de fibres dans le SOLIDE | C20: 0.7 | I20: définition du CPh70
B21: fraction volumique de résine dans le SOLIDE | C21: 0.3 | I21: complément à 1 − 0.70
B22: porosité φ | C22: 0.01 | I22: CPh70 : matériau dense (TACOT : 0.80)
B23: ρ intrinsèque fibres [kg/m³] | C23: 1600 | I23: Description!A11 du classeur TACOT 3.0
B24: ρ intrinsèque résine [kg/m³] | C24: 1200 | I24: Description!A12
B25: rendement en char de la résine | C25: 0.5 | I25: 'Pyrolysis model'!A32:A34 et B18:C19
A27: §3 — CALCUL PAS À PAS
A28: > | B28: Étape 1 — composition du gaz de pyrolyse : elle est HÉRITÉE, pas recalculée | I28: Y_g(CPh70) = Y_g(TACOT), par H1 + H2
B29: Gaz de pyrolyse | C29: C | D29: H | E29: O | F29: Somme
B30: reprise de l'onglet TACOT (chaîne complète : Sykes table I) | C30: ='TACOT'!C66 -> 0.20594711 | D30: ='TACOT'!D66 -> 0.67898448 | E30: ='TACOT'!E66 -> 0.11506842 | F30: =SUM(C30:E30) -> 1
B31: Toute la chaîne de traçabilité du gaz est celle de l'onglet TACOT : table I de Sykes → réduction toluène/xylénol → renormalisation par 100.30 → sommation atomique. Elle n'est PAS refaite ici : la résine est la même, donc le gaz est le même.
A32: > | B32: Étape 2 — char : pondération générale des constituants | I32: n_E(char) = Σ_i (m_char,i / M_i) · ν_E,i
B33: Fibres : carbone pur (ν_C = 1, M = M_C). Résine carbonisée : carbone pur également. La somme pondérée de deux compositions identiques est cette composition, quelles que soient les masses : le char vaut C:1.0 pour TOUT rapport fibres/résine. C'est le point qui rendrait le calcul faux avec des fibres de silice ou un char retenant H/O.
A34: > | B34: Étape 3 — fractions volumiques réelles à partir de la porosité | I34: ε_i = (1 − φ) · f_i
B35: Fractions volumiques | C35: fibres ε_f | D35: résine ε_m | E35: pores φ | F35: Somme
B36: ε = (1 − φ)·f | C36: =(1-$C$22)*$C$20 -> 0.693 | D36: =(1-$C$22)*$C$21 -> 0.297 | E36: =$C$22 -> 0.01 | F36: =SUM(C36:E36) -> 1
A37: > | B37: Étape 4 — bilan de phase solide : masses volumiques et couplage | I37: ρ_v = ε_f·ρ_f + ε_m·ρ_m ; ρ_c = ε_f·ρ_f + Y·ε_m·ρ_m
B38: ρ vierge [kg/m³] | C38: =C36*$C$23+D36*$C$24 -> 1465.2 | I38: attendu 1465.2 (TACOT : 280 — soit 5.2 fois plus dense)
B39: ρ char [kg/m³] | C39: =C36*$C$23+$C$25*D36*$C$24 -> 1287 | I39: attendu 1287.0 (TACOT : 220)
B40: fibres en % de la masse vierge | C40: =C36*$C$23/C38*100 -> 75.675676 | I40: attendu 75.7 % (TACOT : 57.1 %) — le CPh70 est un matériau riche en fibres
B41: gaz de pyrolyse libéré [kg/m³] | C41: =C38-C39 -> 178.2 | I41: attendu 178.2 kg/m³
B42: … soit en % de la masse vierge | C42: =(C38-C39)/C38*100 -> 12.162162 | I42: 12.2 % contre 21.4 % pour le TACOT : deux fois moins de gaz par unité de masse
B43: couplage k = B'g / B'c = (ρ_v − ρ_c)/ρ_c | C43: =(C38-C39)/C39 -> 0.13846154 | I43: attendu 0.1385 — la SEULE grandeur qui distingue le CPh70 du TACOT
A45: §4 — RÉSULTAT : CE QUI ENTRE DANS LE XML
...

Sheet ZURAM
A1: ZURAM® 18/50 — carbone/phénolique DLR
A2: Chaîne INVERSE du TACOT : la donnée primaire est une composition élémentaire MASSIQUE mesurée, pas une spéciation moléculaire
A3: Fichier(s) XML : data/mixtures/zuram-air.xml · zuram-pyrogas.xml
A5: §0 — FICHE D'IDENTITÉ
B6: Matériau | C6: ZURAM® 18/50, ablateur carbone/phénolique du DLR | I6: 'ZURAM_official'!A4 du classeur Tacot_Zuram_Calcarb_database_v4.3.1.ods
B7: Renfort | C7: préforme Mersen Calcarb CBCF 18/2000 — « 18 » = 180 kg/m³ nominal | I7: 'Calcarb_official'!D15 ; note de version 4.3.0
B8: Résine | C8: phénolique catalysée à l'hexamine (HMTA) — novolac DÉDUIT, non déclaré | I8: [THo] Aerosp. Sci. Technol. 119 (2021) 107079, § 4.2
B9: « 50 » du nom | C9: teneur en résine, en % masse de la recette — CONFIRMÉ | I9: Pagan et al. 2017, table 1 : les variantes −25 % et −50 % de résine s'appellent 18/43 et 18/33, soit exactement 42.857 % et 33.333 %
B10: Source du gaz | C10: campagne AblaNTIS du VKI, fractions MASSIQUES élémentaires | I10: 'ZURAM_official'!E87:E89
B11: Compositions du XML | C11: BLedge (-bl) · VKIZuramPyroGas (-py) · Char (-char, -char-elem C) | I11: reproduit le cas de référence AblaNTIS carbonPhenolInAir
A13: §1 — HYPOTHÈSES
A14: H1 | B14: La donnée primaire est la composition élémentaire MASSIQUE du gaz, mesurée — il n'y a pas de spéciation moléculaire à sommer. | I14: C'est la différence de fond avec le TACOT : ici le calcul se réduit à une conversion masse → mole. La contrepartie est que la traçabilité s'arrête à trois décimales, la source [4] VKI_ZURAM_characterization n'étant pas publique.
A15: H2 | B15: Conversion effectuée avec les masses molaires DU CLASSEUR (C 12.0107, H 1.00794, O 15.999). | I15: Elles seules reproduisent 'ZURAM_official'!D87:D89 au 4e-16 près. Les masses usuelles donneraient le même résultat à l'arrondi près, mais pas la reproduction exacte.
A16: H3 | B16: Le gaz est déclaré sans azote, bien que la résine en contienne 1.44 % (hexamine). | I16: [THo] mesure un rendement massique constant de 1.5 % de NH3 au-dessus de 500 °C. Comme pour le TACOT, l'azote est traité comme un composé de catalyseur, hors squelette.
A17: H4 | B17: Le char est du carbone pur : C:1.0. | I17: [THo] mesure pourtant C 96.36 / N 0.13 / H 0.08 / O 3.43 % à 800 °C, et le souligne explicitement. L'hypothèse reste licite en ablation (paroi > 2000 K) et c'est elle qui ferme le mieux le bilan (§5, contrôle C).
A18: H5 | B18: Microstructure : densité intrinsèque de matrice INCHANGÉE à la pyrolyse (pure perte de volume). | I18: Anomalie ouverte n° 3 du classeur : « Intrinsic density of charred resin not well evaluated by He pycnometry ». N'affecte que ρ_c et donc k, pas le XML.
A19: H6 | B19: Liste d'espèces = les 20 espèces gazeuses du cas AblaNTIS + C(gr). | I19: Le but est de reproduire EXACTEMENT la table B' de référence Bprime_carbonPhenolInAir_AblaNTIS.txt : on reprend sa liste à l'identique.
A21: §2 — DONNÉES D'ENTRÉE
A22: > | B22: Gaz de pyrolyse — fractions massiques élémentaires mesurées | I22: 'ZURAM_official'!E87:E89
C23: C | D23: H | E23: O | F23: Somme
B24: y_E — fraction massique [-] | C24: 0.457 | D24: 0.162 | E24: 0.381 | F24: =SUM(C24:E24) -> 1
B25: M_E [g/mol] — masses du classeur | C25: =Constantes!$D$7 -> 12.0107 | D25: =Constantes!$D$8 -> 1.00794 | E25: =Constantes!$D$9 -> 15.999
B26: x_E du classeur ('ZURAM_official'!D87:D89) | C26: 0.17094154 | D26: 0.72207125 | E26: 0.10698721
A28: > | B28: Résine vierge et char — campagne [THo] (analyseur élémentaire, fig. 7) | I28: % masse
C29: C | D29: H | E29: N | F29: O | G29: Somme
B30: résine vierge [% masse] | C30: 75.21 | D30: 5.75 | E30: 1.44 | F30: 14.13 | G30: =SUM(C30:F30) -> 96.53
B31: char à 800 °C [% masse] | C31: 96.36 | D31: 0.08 | E31: 0.13 | F31: 3.43 | G31: =SUM(C31:F31) -> 100
B32: La somme de l'analyse de résine vaut 96.5 % (relevé graphique de la fig. 7) : l'étape 1 du contrôle C la renormalise à 100 %. [THo] commente lui-même la discordance sur l'oxygène entre analyseur élémentaire et micropyrolyse, imputée aux composés lourds non détectés.
A34: > | B34: Microstructure — 'ZURAM_official'!D12:F21 | I34: fractions volumiques et densités intrinsèques
B35: Fractions volumiques | C35: pores | D35: fibres | E35: résine | F35: Somme | G35: ρ intrinsèque [g/cm³]
B36: vierge | C36: 0.707299 | D36: 0.129973 | E36: 0.162729 | F36: =SUM(C36:E36) -> 1.000001
B37: char | C37: 0.769174 | D37: 0.129973 | E37: 0.100854 | F37: =SUM(C37:E37) -> 1.000001
B38: densité intrinsèque [g/cm³] | C38: — | D38: 1.5772 | E38: 1.3151
B39: Piège d'unités : l'en-tête du classeur annonce [kg/m³] mais les valeurs sont en g/cm³. Anomalie ouverte n° 2 : 0.129973 × 1577.2 = 205.0 kg/m³ de fibres, soit 14 % de plus que les 180 kg/m³ nominaux de la préforme CBCF 18/2000.
A41: > | B41: Cinétique de pyrolyse — 'ZURAM_official'!B80:B83 | I41: les f_i ont été divisées par la fraction massique de résine pour porter sur la résine seule (B77)
B42: Réaction | C42: f_i [-] | D42: log10 A | E42: E/R [K] | F42: m
B43: réaction 1 | C43: 0.03507 | D43: 5.33 | E43: 8178.5 | F43: 4.3
B44: réaction 2 | C44: 0.027687 | D44: 8.69 | E44: 16068.4 | F44: 3.7
B45: réaction 3 | C45: 0.095981 | D45: 10.6 | E45: 21612.9 | F45: 2.57
B46: réaction 4 | C46: 0.221495 | D46: 11.67 | E46: 26423.8 | F46: 4.63
...

Sheet SC-1008
A1: SC-1008 — résol phénol-formaldéhyde (matrice du PICA)
A2: Gaz obtenu par FERMETURE ÉLÉMENTAIRE sur un motif chimique idéalisé, validé contre une mesure indépendante
A3: Fichier(s) XML : data/mixtures/sc1008-air.xml · sc1008-pyrogas.xml
A5: §0 — FICHE D'IDENTITÉ
B6: Résine | C6: Durite™ SC-1008, Hexion / Bakelite Synthetics (ex-Borden) | I6: [Wo] J. Anal. Appl. Pyrolysis 122 (2016) 258-267, § 2.2
B7: Type | C7: RÉSOL phénol-formaldéhyde, monocomposant, réticulant par chauffage seul | I7: excès de formaldéhyde, catalyse basique : porte déjà ses méthylols, durcit sans durcisseur
B8: Emploi | C8: matrice du PICA, sur préforme carbone FiberForm | I8: densité PICA 0.274 g/cm³ ± 10 %, porosité 0.8 ± 10 %
B9: Livraison | C9: 20-25 % isopropanol · 11-18 % phénol libre · 0.6-2 % formaldéhyde libre | I9: [Wo] § 2.2 — le phénol libre part en région 1 sans venir du réseau
B10: Sources | C10: [TS] Trick & Saliba, Carbon 33 (1995) 1509-1515 · [Wo] Wong et al. 2016 | I10: sc1008_bprime/resine_sc1008.md
B11: Compositions du XML | C11: air (-bl) · sc1008_pyro (-py) · sc1008_char (-char, -char-elem C)
A13: §1 — HYPOTHÈSES
A14: H1 | B14: Une résine résol cuite = un cycle phénolique + ses ponts méthylène : motif C(6+b)H6O. | I14: Le nombre de ponts b n'est pas libre : le phénol a 3 sites réactifs (2 ortho + 1 para) et un pont est partagé entre 2 cycles, d'où b = 1.5 à réseau saturé.
A15: H2 | B15: PAS D'AZOTE dans le gaz — et cette fois ce n'est pas une approximation. | I15: Un résol réticule sans durcisseur : il n'y a pas d'hexaméthylènetétramine dans la formulation. Le gaz est NATIVEMENT C/H/O. L'argument que le TACOT (2.35 % N) et le ZURAM (1.4 %) doivent construire est ici sans objet.
A16: H3 | B16: Le char est du carbone pur ⇒ H et O traversent la pyrolyse sans être touchés. | I16: Conséquence remarquable : H/O(gaz) = H/O(résine) INDÉPENDAMMENT du rendement en char. C'est l'invariant du §5, un test qui ne dépend d'aucune hypothèse fragile.
A17: H4 | B17: Rendement en char Y = 0.55. | I17: Ce n'est PAS la moyenne des trois sources (0.545 / 0.55-0.60 / 0.62) : le milieu arithmétique 0.575 s'écarte de [TS] de 8.9 %. 0.55 est la seule valeur qui tombe dans la fourchette ATG ET reproduise la composition de [TS] à 1.5 %.
A18: H5 | B18: La borne haute Y = 0.62 de [Wo] est PROPRE AU PICA et ne vaut pas pour la résine seule. | I18: La préforme carbone capte des radicaux pendant la pyrolyse et relève le rendement — [Wo] l'observe directement : H2 divisé par ~5 par rapport à la résole nue.
A19: H6 | B19: Liste d'espèces = les 25 de la table B' de référence + phénol + C(gr). | I19: Le phénol et le crésol sont les produits dominants EN MASSE de la pyrolyse d'un résol ([TS] région 1 ; [Wo] table 1) : les omettre appauvrirait l'équilibre pariétal.
A21: §2 — DONNÉES D'ENTRÉE
B22: nombre de ponts méthylène par cycle, b | C22: 1.5 | I22: 3 sites réactifs / 2 cycles par pont — cf. H1
B23: rendement en char de la résine, Y | C23: 0.55 | I23: recoupement [TS] (0.545) et ATG SC-1008 nue (0.55-0.60) — cf. H4
B24: composition mesurée de [TS] — C | C24: 0.2564 | I24: reconstruite au §5 depuis les tables 2 et 4 de Trick & Saliba (LMS = 50/50 phénol/crésol)
B25: H | C25: 0.6388
B26: O | C26: 0.1048
A28: §3 — CALCUL PAS À PAS
A29: > | B29: Étape 1 — construire le motif de la résine cuite | I29: phénol C6H6O + b·CH2O − b·H2O
B30: Brique | C30: coefficient | D30: ν_C | E30: ν_H | F30: ν_O
B31: phénol C6H6O | C31: 1 | D31: 6 | E31: 6 | F31: 1
B32: + formaldéhyde CH2O | C32: =$C$22 -> 1.5 | D32: 1 | E32: 2 | F32: 1
B33: − eau de condensation H2O | C33: =-$C$22 -> -1.5 | D33: 0 | E33: 2 | F33: 1
B34: MOTIF CUIT — ν_E = Σ coeff · ν | D34: =SUMPRODUCT($C$31:$C$33,D31:D33) -> 7.5 | E34: =SUMPRODUCT($C$31:$C$33,E31:E33) -> 6 | F34: =SUMPRODUCT($C$31:$C$33,F31:F33) -> 1
B35: Avec b = 1.5 : C7.5H6O. Noter que H et O sont RIGOUREUSEMENT insensibles à b (+2b des formaldéhydes, −2b des eaux) : seul le carbone bouge. C'est la raison profonde de l'invariant H/O du §5.
A36: > | B36: Étape 2 — masse molaire et composition massique du motif | I36: M = ν_C·M_C + ν_H·M_H + ν_O·M_O ; w_E = ν_E·M_E / M
C37: C | D37: H | E37: O | F37: M [g/mol]
B38: ν_E · M_E [g/mol] | C38: =D34*Constantes!$C$7 -> 90.0825 | D38: =E34*Constantes!$C$8 -> 6.048 | E38: =F34*Constantes!$C$9 -> 15.999 | F38: =SUM(C38:E38) -> 112.1295
B39: w_E [% masse] | C39: =C38/$F$38*100 -> 80.337913 | D39: =D38/$F$38*100 -> 5.3937635 | E39: =E38/$F$38*100 -> 14.268324 | F39: =SUM(C39:E39) -> 100
B40: Attendu : M = 112.13 g/mol, soit C 80.3 % / H 5.4 % / O 14.3 % en masse. L'écart résol (b = 1.5) / novolac (b = 1) ne vaut que 1.1 point sur C — plus PETIT que la dispersion entre deux novolacs réellement mesurés (TACOT 77.4 vs ZURAM 79.1). L'analyse C/H/O ne permet donc PAS d'identifier le type de résine ; seul l'azote le fait.
A41: > | B41: Étape 3 — fermeture élémentaire sur 100 g de résine : gaz = résine − char | I41: n_E(gaz) = n_E(résine) − n_E(char) ; n_C(char) = Y·100 / M_C
B42: Base 100 g de résine vierge | C42: C | D42: H | E42: O | F42: Somme | G42: masse [g]
B43: résine — moles d'atomes | C43: =100/$F$38*D34 -> 6.6886948 | D43: =100/$F$38*E34 -> 5.3509558 | E43: =100/$F$38*F34 -> 0.89182597 | F43: =SUM(C43:E43) -> 12.931477 | G43: =C43*Constantes!$C$7+D43*Constantes!$C$8+E43*Constantes!$C$9 -> 100
B44: char — carbone pur, Y = 0.55 | C44: =$C$23*100/Constantes!$C$7 -> 4.5791358 | D44: 0 | E44: 0 | F44: =SUM(C44:E44) -> 4.5791358 | G44: =$C$23*100 -> 55
...

Sheet MX-4926
A1: MX-4926 — carbone/phénolique chargé noir de carbone
A2: Matrice SC-1008 : le gaz est HÉRITÉ · démontre que le taux de charge n'entre pas dans le XML, et que la fermeture Σw = 1 tronque une des plages annoncées
A3: Fichier(s) XML : data/mixtures/mx4926-air.xml
A5: §0 — FICHE D'IDENTITÉ
B6: Matériau | C6: MX-4926 — carbone/phénolique chargé | I6: matériau de tuyère de moteur à propergol solide
B7: Renfort | C7: fibres de carbone ex-rayon (ex-cellulose), tissu satin de 5 ou de 8 | I7: le satin accommode les formes complexes et tient la stabilité dimensionnelle
B8: Matrice | C8: résol phénol-formaldéhyde SC-1008 — IDENTIQUE au PICA | I8: cf. onglet SC-1008 §0 ; liant à haut rendement en char
B9: Charge | C9: noir de carbone | I9: optimise l'isolation thermique et la formation du char
B10: Source du gaz | C10: route C, HÉRITÉE du SC-1008 (résine inchangée) | I10: mx4926_bprime/composition_mx4926.md §2.1
B11: Compositions du XML | C11: air (-bl) · mx4926_pyro (-py) · mx4926_char (-char, -char-elem C) | I11: mx4926_bprime/README.md
A13: §1 — HYPOTHÈSES
A14: H1 | B14: La matrice est RIGOUREUSEMENT le SC-1008 de l'onglet précédent : même motif C7.5H6O, même rendement en char. | I14: C'est la seule chose dont dépend la composition du gaz. Tout le §3 de l'onglet SC-1008 s'applique tel quel et n'est PAS refait ici.
A15: H2 | B15: Le renfort ex-rayon ne dégaze pas : une fibre de carbone est déjà le produit d'une pyrolyse. | I15: Perte de masse nulle jusqu'au domaine de sublimation. Contre-exemple : le liège, qui pyrolyse — son onglet doit alors fermer sur DEUX constituants.
A16: H3 | B16: Le noir de carbone est inerte et ne dégaze pas non plus. | I16: Carbone quasi pur (97-99 % C). Du point de vue du bilan de surface il se comporte exactement comme des fibres.
A17: H4 | B17: Les trois constituants carbonisent vers le carbone pur ⇒ char C:1.0 quelles que soient les proportions. | I17: La pondération n_E(char) = Σ_i (m_char,i/M_i)·ν_E,i se réduit à C:1.0 dès que tous les constituants donnent le même élément.
A18: H5 | B18: Aucune grandeur volumique n'entre dans le bilan de surface. | I18: Le bilan est écrit sur des fractions massiques élémentaires, donc normalisées : ni ρ, ni porosité (Constantes §4).
A19: H6 | B19: Les trois plages de composition annoncées doivent se refermer à 100 %. | I19: Elles sont données indépendamment les unes des autres, mais ne peuvent pas l'être : c'est l'objet de l'étape 1 du §3.
A21: §2 — DONNÉES D'ENTRÉE
B22: Fractions MASSIQUES annoncées | C22: borne basse | D22: borne haute
B23: renfort — fibres de carbone ex-rayon | C23: 0.41 | D23: 0.56
B24: matrice — résol SC-1008 | C24: 0.31 | D24: 0.37
B25: charge — noir de carbone | C25: 0.11 | D25: 0.16
B26: SOMME | C26: =SUM(C23:C25) -> 0.83 | D26: =SUM(D23:D25) -> 1.09
B27: Ces deux sommes sont le point de départ de tout l'onglet : 0.830 et 1.090. Elles encadrent 1 sans le valoir — les trois plages ne sont donc pas indépendantes.
B28: rendement en char de la RÉSINE, Y | C28: ='SC-1008'!C23 -> 0.55 | I28: lien vers l'onglet SC-1008 §2 : 0.55, recoupement [TS] et ATG
B29: ρ intrinsèque fibres [kg/m³] | C29: 1600 | I29: fibres ex-cellulose — Description!A11 du classeur TACOT 3.0 ; le rayon EST une cellulose régénérée
B30: ρ intrinsèque résol cuit [kg/m³] | C30: 1250 | I30: valeur usuelle d'un phénolique cuit (1200-1300)
B31: ρ intrinsèque noir de carbone [kg/m³] | C31: 1800 | I31: valeur usuelle (1800-2100)
B32: densité publiée du MX-4926 [kg/m³] | C32: 1450 | I32: ≈ 1.45 g/cm³ — sert au contrôle C du §5, pas au calcul
A34: §3 — CALCUL PAS À PAS
A35: > | B35: Étape 1 — FERMETURE : les plages effectives ne sont pas les plages annoncées | I35: w_i,min_eff = MAX(w_i,min ; 1 − Σ_{j≠i} w_j,max) et symétriquement
B36: Plages EFFECTIVES après fermeture | C36: min | D36: max | E36: annoncé min | F36: annoncé max | G36: largeur perdue
B37: renfort | C37: =MAX(C23,1-D24-D25) -> 0.47 | D37: =MIN(D23,1-C24-C25) -> 0.56 | E37: =C23 -> 0.41 | F37: =D23 -> 0.56 | G37: =(D23-C23)-(D37-C37) -> 0.06
B38: matrice | C38: =MAX(C24,1-D23-D25) -> 0.31 | D38: =MIN(D24,1-C23-C25) -> 0.37 | E38: =C24 -> 0.31 | F38: =D24 -> 0.37 | G38: =(D24-C24)-(D38-C38) -> 0
B39: charge | C39: =MAX(C25,1-D23-D24) -> 0.11 | D39: =MIN(D25,1-C23-C24) -> 0.16 | E39: =C25 -> 0.11 | F39: =D25 -> 0.16 | G39: =(D25-C25)-(D39-C39) -> 0
B40: Une seule ligne a une largeur perdue non nulle : le RENFORT, dont la borne basse passe de 41 % à 47 %. Pour descendre à 41 % de fibres il faudrait 59 % de résine + charge, alors que le maximum admissible est 37 + 16 = 53 %. Les 41 % annoncés ne sont atteignables avec AUCUN couple (résine, charge) admissible. Les plages de la matrice et de la charge survivent intactes — et c'est la matrice qui pilote toute la suite (étape 4).
A41: > | B41: Étape 2 — composition retenue : le centroïde du domaine admissible | I41: centroïde d'AIRE du polygone (5 sommets), pas une moyenne de grille
B42: Composition retenue (fractions massiques) | C42: renfort | D42: matrice | E42: charge | F42: Somme
B43: centroïde exact du polygone admissible | C43: 0.52202381 | D43: 0.34166667 | E43: =1-C43-D43 -> 0.13630952 | F43: =SUM(C43:E43) -> 1
B44: Les deux valeurs bleues sont produites par mx4926_bprime/composition_mx4926_verification.py §2 (clipping de Sutherland-Hodgman, puis formule du centroïde d'aire) : un polygone à 5 sommets ne se moyenne pas à la main. La CHARGE n'est pas saisie : elle est fermée par différence, de sorte que Σw = 1 exactement quel que soit l'arrondi des deux autres — saisir les trois arrondies à 1e-6 briserait la fermeture de 1e-6. Le contrôle D du §5 vérifie que le point tombe bien dans les plages effectives ci-dessus.
...

Sheet Liège-phénolique
A1: Liège / phénolique (cork phenolic) — 80 / 20 en masse
A2: Le SEUL matériau du dépôt dont le RENFORT PYROLYSE AUSSI : le gaz est le mélange de deux gaz, et le rapport renfort/résine entre dans la table B'
A3: Fichier(s) XML : data/mixtures/cork-air.xml · cork-pyrogas.xml
A5: §0 — FICHE D'IDENTITÉ
B6: Matériau | C6: composite liège / résine phénolique, 80 % liège / 20 % résine en MASSE du solide | I6: matériau de type P50 (Amorim) — IXV et QARMAN
B7: Renfort | C7: liège (Quercus suber) — subérine 45 / lignine 27 / polysaccharides 12 / tanins 6 / céroïdes 6 % | I7: IL PYROLYSE : c'est l'essentiel du gaz produit
B8: Résine | C8: novolac C7H6O, rendement en char 50 % | I8: même motif que TACOT, PICA, CPh70
B9: Rendement en char du composite | C9: 20 % — mesuré par TGA sur le cork P50 (argon, 10 K/min, plateau 780-1650 K) | I9: Sakraker et al., CEAS Space Journal 14:377-393 (2022)
B10: Sources | C10: cork_bprime/mise_en_donnees_cork.md · cork_pyrolysis_data.py
B11: Compositions du XML | C11: air (-bl) · cork_pyro (-py) · cork_char (-char, -char-elem C)
A13: §1 — HYPOTHÈSES
A14: H1 | B14: LE RENFORT PYROLYSE. Le gaz est produit par les DEUX constituants, mélangés au prorata des masses réellement dégazées. | I14: C'est toute la différence avec un carbone/phénolique. Conséquence : le rapport liège/résine entre DANS la composition du gaz, donc dans la table B' — ce qui n'était pas le cas du CPh70.
A15: H2 | B15: « 80 % de liège » se lit en MASSE, pas en volume. | I15: Piège d'énoncé : le liège est très léger (≈ 120 kg/m³ contre 1200 pour la résine). 80 % en VOLUME ne ferait que 28.6 % en masse — un tout autre matériau (gaz C:0.277, char 39.3 %, k = 1.545).
A16: H3 | B16: Analyse élémentaire du liège retenue : C 62.4 / H 8.5 / O 28.4 % masse (littérature, sec sans cendres). | I16: PROVENANCE À CONFIRMER : valeurs usuelles pour Quercus suber, non vérifiées sur une source primaire accessible. Le contrôle biochimique du §5 est, lui, traçable ligne à ligne. L'azote (~0.6 %) est négligé — le retenir ajouterait une 4e composante au gaz.
A17: H4 | B17: Rendement en char du liège DÉDUIT du composite mesuré et de la résine : 0.80·y + 0.20·0.50 = 0.20 ⇒ y = 12.5 %. | I17: La TGA ne sépare pas les deux constituants. Lever l'hypothèse « résine à 50 % » demanderait une seconde TGA, sur la résine seule ou sur le liège seul.
A18: H5 | B18: Les deux constituants carbonisent vers du carbone pur ⇒ char C:1.0. | I18: Un char de liège réel retient un peu de H et de O : le §5 chiffre cette variante (char multi-élément C:0.864, H:0.108, O:0.027) — et rappelle qu'il faut alors RETIRER ces atomes du gaz.
A19: H6 | B19: Le couplage stationnaire se calcule sur les MASSES : k = (1 − y)/y = 4.0. | I19: L'identité k = (ρ_v − ρ_c)/ρ_c suppose un volume constant, que ce matériau ne respecte PAS : le char se rétracte (V_char/V_vierge ≈ 0.32). Les densités donneraient k = 0.61, six fois trop peu.
A21: §2 — DONNÉES D'ENTRÉE
A22: > | B22: Analyse élémentaire du liège — valeurs de littérature (RETENUES) | I22: % masse, sec sans cendres
C23: C | D23: H | E23: O | F23: Somme
B24: liège [% masse] | C24: 62.4 | D24: 8.5 | E24: 28.4 | F24: =SUM(C24:E24) -> 99.3
B25: La somme vaut 99.3 % et non 100 : l'étape 1 renormalise. C'est exactement ce que fait cork_pyrolysis_data.py.
A27: > | B27: Constituants biochimiques du liège et leurs unités de répétition (sert au contrôle du §5) | I27: M_i = Σ_E ν_E,i · M_E
B28: Constituant — unité de répétition | C28: % masse | D28: ν_C | E28: ν_H | F28: ν_O | G28: M [g/mol] | H28: rendement en char
B29: subérine — C57H104O12 (glycérol + 3 acides époxy-hydroxy C18, − 3 H2O) | C29: 45 | D29: 57 | E29: 104 | F29: 12 | G29: =D29*Constantes!$C$7+E29*Constantes!$C$8+F29*Constantes!$C$9 -> 981.447 | H29: 0.15
B30: lignine — C10H12O3 (alcool coniférylique, unité guaïacyle) | C30: 27 | D30: 10 | E30: 12 | F30: 3 | G30: =D30*Constantes!$C$7+E30*Constantes!$C$8+F30*Constantes!$C$9 -> 180.203 | H30: 0.45
B31: polysaccharides — C6H10O5 (anhydroglucose) | C31: 12 | D31: 6 | E31: 10 | F31: 5 | G31: =D31*Constantes!$C$7+E31*Constantes!$C$8+F31*Constantes!$C$9 -> 162.141 | H31: 0.15
B32: tanins — C15H14O6 (flavan-3-ol, catéchine) | C32: 6 | D32: 15 | E32: 14 | F32: 6 | G32: =D32*Constantes!$C$7+E32*Constantes!$C$8+F32*Constantes!$C$9 -> 290.271 | H32: 0.4
B33: céroïdes — C30H50O (friedéline) | C33: 6 | D33: 30 | E33: 50 | F33: 1 | G33: =D33*Constantes!$C$7+E33*Constantes!$C$8+F33*Constantes!$C$9 -> 426.729 | H33: 0.02
B34: SOMME des parts | C34: =SUM(C29:C33) -> 96
B35: Les parts somment à 96 % : le complément (cendres ~1 %, humidité résiduelle, extractibles mineurs) n'est pas de la matière C/H/O identifiée. On renormalise donc sur les 96 % déclarés. Les rendements en char par constituant (dernière colonne) sont des ordres de grandeur d'ATG lente sous inerte — ils servent au contrôle B du §5, pas au calcul du XML.
B37: fraction massique de liège dans le solide | C37: 0.8 | I37: hypothèse H2 — lecture MASSIQUE
B38: fraction massique de résine dans le solide | C38: =1-C37 -> 0.2
B39: rendement en char du COMPOSITE (mesuré, TGA P50) | C39: 0.2 | I39: plateau de 780 à 1650 K, argon, 10 K/min
B40: rendement en char de la RÉSINE | C40: 0.5 | I40: valeur classique novolac (énoncé) — même valeur que le TACOT
B41: motif de la résine — ν_C | C41: 7 | I41: novolac linéaire C7H6O, cf. Constantes §3
B42: ν_H | C42: 6
B43: ν_O | C43: 1
B44: ρ vierge / ρ char mesurés du P50 [kg/m³] | C44: 465.6 | I44: Sakraker et al. : 464.5 et 466.7 vierge
C45: 289.1 | I45: Sakraker et al. : 279.9 et 298.4 char — n'entre PAS dans k, cf. H6
...

Sheet Chêne
A1: Bois de chêne — ablateur pyrolysant à un seul constituant
A2: Le cas le plus simple des ablateurs pyrolysants : TOUT le solide pyrolyse, sans résine ni renfort inerte — une seule fermeture élémentaire bois − char
A3: Fichier(s) XML : data/mixtures/oak-air.xml · oak-pyrogas.xml
A5: §0 — FICHE D'IDENTITÉ
B6: Matériau | C6: bois de chêne massif (Quercus robur / Q. petraea), SEC, sans résine | I6: feuillu — à ne pas confondre avec le liège (Q. suber)
B7: Constituants | C7: cellulose 43 / hémicelluloses 22 / lignine S+G 25 / ellagitanins 8 % | I7: IL PYROLYSE ENTIÈREMENT : 80 % du bois part en gaz
B8: Rendement en char | C8: 20 % en masse | I8: donnée de l'énoncé
B9: Unité de répétition globale | C9: C6H8.7O3.95 — soit CH1.45O0.66 par atome de carbone | I9: calculée à l'étape 5 du §3
B10: Sources | C10: oak_bprime/mise_en_donnees_chene.md · oak_pyrolysis_data.py
B11: Compositions du XML | C11: air (-bl) · oak_pyro (-py) · oak_char (-char, -char-elem C)
A13: §1 — HYPOTHÈSES
A14: H1 | B14: UN SEUL CONSTITUANT, QUI PYROLYSE ENTIÈREMENT. Gaz = bois − char, sans mélange de gaz. | I14: Route C (fermeture élémentaire), mais partant d'une ANALYSE élémentaire et non d'un motif idéalisé. Pas de rapport renfort/résine : contrairement au liège, rien d'autre que le rendement en char ne pondère le gaz.
A15: H2 | B15: Bois SEC. L'humidité (8-12 % dans un bois stabilisé à l'air) n'est pas comptée. | I15: Elle partirait intégralement en vapeur d'eau, donc dans le gaz : le §6 chiffre la variante (gaz plus riche en H et O, k plus grand).
A16: H3 | B16: Analyse élémentaire du chêne retenue : C 50.0 / H 6.1 / O 43.9 % masse (littérature, sec sans cendres). | I16: PROVENANCE À CONFIRMER : valeurs usuelles pour le bois de chêne, non vérifiées sur une source primaire accessible. Le contrôle biochimique du §5 les retrouve à 0.4 point près. L'azote (0.1-0.3 %) est négligé.
A17: H4 | B17: Rendement en char : 20 % en masse du bois sec. | I17: Donnée de l'énoncé. C'est LE paramètre du calcul : il fixe à la fois le carbone du gaz et le couplage k (§6). Le contrôle par additivité des constituants donne 22 %.
A18: H5 | B18: Le bois carbonise vers du carbone pur ⇒ char C:1.0. | I18: Un charbon de bois réel retient H et O (d'autant plus que la carbonisation est froide) : le §5 chiffre la variante — et rappelle qu'il faut alors RETIRER ces atomes du gaz.
A19: H6 | B19: Le couplage stationnaire se calcule sur les MASSES : k = (1 − y)/y = 4.0. | I19: L'identité k = (ρ_v − ρ_c)/ρ_c suppose un volume constant ; le bois se rétracte en carbonisant (retrait volumique typiquement 30-50 %).
A21: §2 — DONNÉES D'ENTRÉE
A22: > | B22: Analyse élémentaire du chêne — valeurs de littérature (RETENUES) | I22: % masse, sec sans cendres
C23: C | D23: H | E23: O | F23: Somme
B24: chêne [% masse] | C24: 50 | D24: 6.1 | E24: 43.9 | F24: =SUM(C24:E24) -> 100
B25: La somme vaut 100 % : l'étape 1 renormalise quand même, pour qu'une analyse mesurée (qui ne somme jamais exactement à 100) puisse être collée ici telle quelle.
A27: > | B27: Constituants biochimiques du chêne et leurs unités de répétition (sert au contrôle du §5) | I27: M_i = Σ_E ν_E,i · M_E
B28: Constituant — unité de répétition | C28: % masse | D28: ν_C | E28: ν_H | F28: ν_O | G28: M [g/mol] | H28: rendement en char
B29: cellulose — C6H10O5 (anhydroglucose) | C29: 43 | D29: 6 | E29: 10 | F29: 5 | G29: =D29*Constantes!$C$7+E29*Constantes!$C$8+F29*Constantes!$C$9 -> 162.141 | H29: 0.1
B30: hémicelluloses — C5H8O4 (anhydroxylose, glucuronoxylane) | C30: 22 | D30: 5 | E30: 8 | F30: 4 | G30: =D30*Constantes!$C$7+E30*Constantes!$C$8+F30*Constantes!$C$9 -> 132.115 | H30: 0.2
B31: lignine S — C11H14O4 (alcool sinapylique) | C31: 16 | D31: 11 | E31: 14 | F31: 4 | G31: =D31*Constantes!$C$7+E31*Constantes!$C$8+F31*Constantes!$C$9 -> 210.229 | H31: 0.35
B32: lignine G — C10H12O3 (alcool coniférylique) | C32: 9 | D32: 10 | E32: 12 | F32: 3 | G32: =D32*Constantes!$C$7+E32*Constantes!$C$8+F32*Constantes!$C$9 -> 180.203 | H32: 0.45
B33: tanins — C41H26O26 (vescalagine, ellagitanin) | C33: 8 | D33: 41 | E33: 26 | F33: 26 | G33: =D33*Constantes!$C$7+E33*Constantes!$C$8+F33*Constantes!$C$9 -> 934.633 | H33: 0.4
B34: SOMME des parts | C34: =SUM(C29:C33) -> 98
B35: Les parts somment à 98 % : le complément (cendres ~0.4 %, groupes acétyles des hémicelluloses, extractibles mineurs) n'est pas de la matière C/H/O identifiée. On renormalise sur les 98 % déclarés. La lignine de feuillu est répartie en 16 % S + 9 % G en masse, soit S/G = 1.52 en moles. Les rendements en char par constituant (dernière colonne) sont des ordres de grandeur d'ATG lente sous inerte — ils servent au contrôle B du §5, pas au calcul du XML.
B37: rendement en char du bois sec | C37: 0.2 | I37: hypothèse H4 — donnée de l'énoncé
B38: ρ vierge [kg/m³] | C38: 700 | I38: chêne sec, ordre de grandeur 650-750 kg/m³ — n'entre PAS dans le XML
B39: V_char / V_vierge (retrait volumique) | C39: 0.55 | I39: HYPOTHÈSE, non mesurée ici — à remplacer par une mesure (§7)
A41: §3 — CALCUL PAS À PAS
A42: > | B42: Étape 1 — renormaliser l'analyse élémentaire du chêne à 100 % | I42: w_E = w_E,brut / Σ w_j,brut
C43: C | D43: H | E43: O | F43: Somme
B44: chêne renormalisé [% masse] | C44: =C24/$F$24*100 -> 50 | D44: =D24/$F$24*100 -> 6.1 | E44: =E24/$F$24*100 -> 43.9 | F44: =SUM(C44:E44) -> 100
A45: > | B45: Étape 2 — bilan de masse sur 100 g de bois sec | I45: m_char = 100 · y ; m_gaz = 100 · (1 − y)
C46: masse [g] | D46: rendement char | E46: char [g] | F46: gaz [g]
...

Sheet Carbone
A1: Carbone graphite — ablateur non pyrolysant
A2: Cas dégénéré : le solide EST le char, il n'y a pas de gaz de pyrolyse · sert de cas de référence physique aux autres onglets
A3: Fichier(s) XML : data/mixtures/carbon-air.xml
A5: §0 — FICHE D'IDENTITÉ
B6: Matériau | C6: graphite pur (carbone massif) | I6: carbon_bprime/bprime_carbon_physique.md
B7: Renfort / résine | C7: sans objet — matériau monolithique | I7: aucune pyrolyse interne
B8: Système chimique | C8: C-N-O : 5 espèces d'air + 3 formes gazeuses du carbone + CO, CO2, CN + C(gr) | I8: 12 espèces au total
B9: Compositions du XML | C9: air (-bl) · pyro = C:1.0 (-py, et définit le char)
A11: §1 — HYPOTHÈSES
A12: H1 | B12: Pas de pyrolyse interne : B'g = 0. | I12: Il n'y a pas de résine à décomposer. Toute la masse injectée vient de la surface, d'où le nom de « cas dégénéré ».
A13: H2 | B13: Le char est le matériau lui-même : carbone pur, C:1.0. | I13: Aucune fermeture élémentaire à faire — c'est la seule mise en données du dépôt où la composition ne se CALCULE pas.
A14: H3 | B14: Équilibre thermochimique à la paroi, char infini. | I14: Le solveur ajoute δ = max(200, 100·B'g) de carbone élémentaire à la composition du bord de couche limite avant de normaliser, puis calcule l'équilibre multiphase.
A15: H4 | B15: C(gr) est indispensable dans la liste d'espèces. | I15: Sans phase condensée, C3 gazeux domine dès 300 K, Y_w,C → 1 et B'c ≈ 200 — non physique. C'est le contrôle du §5, valable pour TOUS les onglets carbonés.
A17: §2 — DONNÉES D'ENTRÉE
B18: bord de couche limite | C18: air : N:0.79, O:0.21 (molaire) | I18: cf. onglet Constantes §2
B19: fraction massique d'oxygène de l'air | C19: =Constantes!D19 -> 0.23290922 | I19: y_O calculé au §2 de l'onglet Constantes
B20: masse volumique du graphite [kg/m³] | C20: 1800 | I20: ordre de grandeur (1600-2200 selon la qualité) — n'entre que dans la récession
A22: §3 — CALCUL PAS À PAS
A23: > | B23: Étape 1 — composition élémentaire du char : directe | I23: le solide est du carbone pur ⇒ x_C = 1
C24: C | D24: N | E24: O | F24: Somme
B25: char (= le matériau) | C25: 1 | D25: 0 | E25: 0 | F25: =SUM(C25:E25) -> 1
A26: > | B26: Étape 2 — gaz de pyrolyse : il n'y en a pas | I26: B'g = 0 dans toutes les commandes bprime de ce matériau
B27: La composition nommée `pyro` du XML vaut néanmoins C:1.0. Ce n'est pas une incohérence : elle sert d'argument à `-py` (le parseur exige une composition valide) et définit le char. Comme elle est appelée avec -b 0.0, elle ne contribue à rien.
A28: > | B28: Étape 3 — le bilan de surface se réduit à une expression fermée | I28: B'c = [Y_e,C + B'g·Y_g,C − Y_w,C(1+B'g)] / (Y_w,C − Y_c,C)
B29: Avec Y_c,C = 1 (char de carbone pur), Y_e,C = 0 (l'air ne contient pas de carbone) et B'g = 0, il ne reste que :
B30: B'c = − Y_w,C / (Y_w,C − 1) = Y_w,C / (1 − Y_w,C)
B31: La seule inconnue est Y_w,C, la fraction massique de carbone dans le gaz d'équilibre à la paroi — c'est elle que le solveur multiphase calcule à (T_w, P).
A33: §4 — RÉSULTAT : CE QUI ENTRE DANS LE XML
B34: Composition élémentaire (fractions molaires) | C34: C | D34: N | E34: O | F34: Somme
B35: pyro / char — valeur portée dans le XML | C35: 1 | D35: — | E35: —
B36: air — valeur portée dans le XML | C36: — | D36: 0.79 | E36: 0.21 | F36: =D36+E36 -> 1
A38: §5 — CONTRÔLES ET VALIDATION CROISÉE
A39: > | B39: Contrôle de recette valable pour TOUS les matériaux carbonés du dépôt | I39: à 300 K, B'g = 0 : régime d'oxydation basse température, C(gr) + O2 → CO2
B40: À 300 K tout l'oxygène de l'air est consommé en CO2. Chaque O2 (2 atomes d'oxygène) emporte un atome de carbone : la masse de carbone ablatée par unité de masse d'air vaut donc y_O · M_C / (2·M_O). Ce nombre ne dépend PAS de la pression.
B41: B'c attendu à 300 K, 1 atm | C41: =C19*Constantes!$C$7/(2*Constantes!$C$9) -> 0.087426483 | I41: attendu 0.0874 — valeur obtenue par bprime sur carbon-air, cork-air, tacot-air…
B42: B'c obtenu si C(gr) manque dans <species> | C42: ≈ 200 | I42: signature sans ambiguïté d'une liste d'espèces incomplète : Y_w,C → 1 et B'c sature sur son plafond interne
A44: §6 — SENSIBILITÉ — régimes physiques (à 1 atm)
B45: Régime | C45: T_w [K] | D45: Phase stable | E45: Espèce gazeuse dominante | F45: Mécanisme
B46: faible ablation | C46: 300 – 700 | D46: C(gr) | E46: CO2, O2, N2 | F46: C(gr) + O2 → CO2
B47: oxydation active | C47: 700 – 3500 | D47: C(gr) | E47: CO, N2, CN | F47: C(gr) + O → CO ; Boudouard C(gr) + CO2 → 2 CO
...

Sheet Silice
A1: Silice SiO2 — char MULTI-ÉLÉMENT
A2: Premier char du dépôt qui n'est pas du carbone (avec le SiC) : montre comment se remplit une composition à plusieurs éléments
A3: Fichier(s) XML : data/mixtures/silica-air.xml
A5: §0 — FICHE D'IDENTITÉ
B6: Matériau | C6: silice pure SiO2 | I6: silice_bprime/silice_bprime.py
B7: Système chimique | C7: Si-N-O : 5 espèces d'air + 5 espèces gazeuses du silicium + 4 phases condensées de SiO2 | I7: SiO2(a-qz), SiO2(b-qz), SiO2(b-crt), SiO2(L)
B8: Binaire dédié | C8: bprime_silica (et non bprime) | I8: le bilan est résolu sur Si, pas sur C
B9: Compositions du XML | C9: air (-bl) · silice (char, -char-elem Si)
A11: §1 — HYPOTHÈSES
A12: H1 | B12: Le char est la silice elle-même, de stœchiométrie SiO2 exacte. | I12: Matériau monolithique : pas de résine, donc pas de gaz de pyrolyse (B'g = 0) et pas de fermeture élémentaire à faire.
A13: H2 | B13: L'élément du bilan est le SILICIUM, pas le carbone. | I13: Règle générale : `-char-elem` doit désigner un élément PRÉSENT dans le char et ABSENT (ou minoritaire) au bord de couche limite. L'oxygène ne conviendrait pas — l'air en contient 21 % molaire.
A14: H3 | B14: Les quatre phases condensées de SiO2 doivent figurer dans <species>. | I14: Même exigence que C(gr) pour les matériaux carbonés : sans phase condensée, le solveur ne peut pas faire précipiter la silice et B'c sature sur une valeur non physique. Ici il faut les quatre polymorphes (quartz α et β, cristobalite β, liquide) pour couvrir toute la plage de température.
A15: H4 | B15: Équilibre thermochimique à la paroi. | I15: Identique aux autres matériaux.
A17: §2 — DONNÉES D'ENTRÉE
B18: stœchiométrie — ν_Si | C18: 1 | I18: SiO2
B19: stœchiométrie — ν_O | C19: 2
B20: masse volumique de la silice [kg/m³] | C20: 2200 | I20: silice vitreuse — n'entre que dans la récession
A22: §3 — CALCUL PAS À PAS
A23: > | B23: Étape 1 — masse molaire du motif | I23: M = ν_Si·M_Si + ν_O·M_O
B24: M(SiO2) [g/mol] | C24: =C18*Constantes!$C$11+C19*Constantes!$C$9 -> 60.0835 | I24: attendu 60.08 g/mol
A25: > | B25: Étape 2 — composition élémentaire, en molaire puis en massique | I25: x_E = ν_E / Σ ν_j ; y_E = ν_E·M_E / M
C26: Si | D26: O | E26: Somme
B27: ν_E (moles d'atomes par motif) | C27: =C18 -> 1 | D27: =C19 -> 2 | E27: =SUM(C27:D27) -> 3
B28: x_E (fraction molaire élémentaire, normalisée) | C28: =C27/$E$27 -> 0.33333333 | D28: =D27/$E$27 -> 0.66666667 | E28: =SUM(C28:D28) -> 1
B29: y_E (fraction massique élémentaire) | C29: =C27*Constantes!$C$11/$C$24 -> 0.46744114 | D29: =D27*Constantes!$C$9/$C$24 -> 0.53255886 | E29: =SUM(C29:D29) -> 1
B30: Attendu : x_Si = 0.3333 / x_O = 0.6667 en molaire, y_Si = 0.4674 / y_O = 0.5326 en masse. Le piège classique est de confondre les deux — le parseur suppose du MOLAIRE par défaut.
A32: §4 — RÉSULTAT : CE QUI ENTRE DANS LE XML
B33: Composition élémentaire | C33: Si | D33: O | E33: Somme | F33: après normalisation par le parseur
B34: valeur portée dans le XML (silice) | C34: 1 | D34: 2 | E34: =SUM(C34:D34) -> 3 | F34: x_Si = 1/3, x_O = 2/3
B35: C'est l'illustration la plus nette de la règle de normalisation automatique (Composition::componentsFromList) : « Si:1.0, O:2.0 » somme à 3, et le parseur le ramène à 1. On peut donc saisir indifféremment des moles brutes, des pourcentages ou des fractions — c'est le RAPPORT qui compte, et écrire directement Si:0.3333, O:0.6667 donnerait exactement le même mélange.
A37: §5 — CONTRÔLES ET VALIDATION CROISÉE
B38: x_Si + x_O après normalisation | C38: =C28+D28 -> 1 | I38: doit valoir 1 exactement
B39: rapport O/Si | C39: =D27/C27 -> 2 | I39: doit valoir 2 — la stœchiométrie de la silice
B40: Le cas de la silice est aussi le CONTRE-EXEMPLE de référence pour les composites : dès que les constituants ne carbonisent pas vers le même produit (fibres de silice + résine phénolique, par exemple), le char devient multi-élément et il faut pondérer par les MASSES de char de chaque constituant : n_E(char) = Σ_i (m_char,i / M_i)·ν_E,i. Le ratio renfort/résine entre alors dans la table B' — cf. onglet CPh70 §6 pour le cas contraire, et l'onglet Liège-phénolique §5 pour un exemple chiffré de pondération.
A42: §6 — SENSIBILITÉ
B43: Sans objet : la stœchiométrie SiO2 est exacte, il n'y a ni rendement en char, ni analyse élémentaire, ni motif de résine à choisir. C'est la mise en données la moins incertaine du classeur — l'incertitude est reportée sur la base thermodynamique des quatre phases condensées et sur l'hypothèse d'équilibre à la paroi.
A45: §7 — RÉPONSE MATÉRIAU (n'entre PAS dans le XML)
B46: couplage k = B'g / B'c | C46: 0 | I46: pas de pyrolyse interne — comme le graphite
B47: ρ_char [kg/m³] | C47: =C20 -> 2200 | I47: la silice fondue est évacuée mécaniquement : la récession réelle dépasse celle donnée par B'c seul
A49: §8 — BLOC XML
...

Sheet SiC
A1: Carbure de silicium SiC — char multi-élément NON congruent
A2: Char à deux éléments qui peut laisser à la paroi SiO2, Si liquide ou carbone : le bilan est suivi sur l'azote de l'air
A3: Fichier(s) XML : data/mixtures/sic-air.xml
A5: §0 — FICHE D'IDENTITÉ
B6: Matériau | C6: carbure de silicium massif β-SiC (dense, fritté ou CVD) | I6: sic_bprime/sic_bprime.py · sic_bprime/README.md
B7: Système chimique | C7: Si-C-N-O : 5 espèces d'air + 6 gaz carbonés + 10 gaz siliciés (SiO, SiO2, SiC, SiC2, Si2C, SiN…) + 9 phases condensées | I7: 30 espèces au total
B8: Phases condensées | C8: C(gr) · Si(cr), Si(L) · SiC(b), SiC(L) · SiO2(a-qz), SiO2(b-qz), SiO2(b-crt), SiO2(L) | I8: une seule forme de chaque famille est valide à une température donnée
B9: Binaire | C9: bprime généralisé : -char sic -char-elem N | I9: aucun binaire dédié (contrairement à bprime_silica)
B10: Compositions du XML | C10: air (-bl) · sic (char, -char)
A12: §1 — HYPOTHÈSES
A13: H1 | B13: Le char est le SiC lui-même, de stœchiométrie Si:C = 1:1 exacte. | I13: Matériau monolithique : pas de résine, donc pas de gaz de pyrolyse (B'g = 0) et pas de fermeture élémentaire à faire.
